Workbook
Name BI: #REF!
Name BI: #REF!
Name COBERTURAS: #REF!
Name COBERTURAS: #REF!
Name COBRC: #REF!
Name COBRC: #REF!
Name complejitos: #REF!
Name SUBLIMITES: #REF!
Name SUBLIMITES: #REF!
Name TC: #REF!
Name UBCINEMEX: 'Ubicaciones total (2)'!$A$1:$M$368
Name UBIC: #REF!

Sheet COASEGURP
A1: Tipo de Operación: | B1:  Coaseguro Suscrip. No Líder
A2: (Coaseguro con otra Compañía). | B2:  Coaseguro Suscrip. Líder
A4: Participación Propia: | B4: 0.7
A5: Compañía Líder: | B5: GRUPO MEXICANO DE SEGUROS, S.A. DE C.V.
A7: Compañías Participantes: | B7: % Participación
A8: GREAT AMERICA = EL AGUILA COMPAÑÍA DE SEGUROS, S.A. DE C.V. | B8: 0.15
A9: SEGUROS ATLAS, S.A. | B9: 0.15
A15: Total, Participación | B15: 100%%
A17: Facturación (Coaseguro Líder): | B17:  Parte de la Compañía.
B18:  Total de la Operación.
A21: Facturación (Coaseguro No Líder) Pagador:
A27: Las COASEGURADORAS acuerdan que la distribución de la participación en el riesgo por sección/ramo es el siguiente:
A30: MONEDA DE LA PÓLIZA.
A32:  Pesos Mexicanos (MXP)
A33:  Dólares (USD)
A36: FORMA DE PAGO DEL ASEGURADO.
A38:  Anual.
A39:  Contado.
A40:  Semestral.
A41:  Trimestral.
A42:  Mensual.
A44: PERIODO DE GRACIA PARA EL PAGO DE LA PRIMA POR PARTE DEL ASEGURADO.
... A64: 
A65: Prima Neta. | B65: ______%
A66:  Recargos por pago fraccionado. ____%
A67:  Sobre comisión. _____%
A69: Se incluye detalle de comisiones por cobertura y/o ramo contable.
A71: COMISIÓN POR ADMINISTRACIÓN DE COASEGURO.
A73: La comisión por administración para la COASEGURADORA LIDER será de: ____0___% sobre la participación de cada COASEGURADORA SEGUIDORA.
A75: SINIESTROS E INDEMNIZACIONES.
A77: Las COASEGURADORAS acuerdan que los ajustes de los siniestros se lleven a cabo a través del panel de ajustadores de la COASEGURADORA LÍDER, asimismo, las indemnizaciones que corresponda a los siniestros procedentes, sea realizado por la COASEGURADORA LÍDER sin la previa autorización de las COASEGURADORAS SEGUIDORAS dentro de los límites siguientes:
A79:  Hasta el __0_% del límite de responsabilidad.
A80:  Hasta un límite máximo de $_____________ (MXP) o (USD).

Sheet Hoja4
G2: COMISION | H2: 0.08
A3: GLOBAL | B3: 1632592.5 | C3: 100.00 | D3: 17,223.85 | E3: 263,986.62 | F3: 1,913,902.97 | H3: =B3*H2 -> 130607.4 | I3: =H9+H16 -> 130607.4
B4: PRIMA NETA | C4: DERECHOS | D4: RECARGOS | E4: IVA | F4: TOTAL
A9: POLIZA 12 MESES | B9: 1088395 | C9: 100.00 | D9: 11,482.57 | E9: 175,996.41 | F9: 1,275,973.98 | H9: =B9*H2 -> 87071.6
B10: PRIMA NETA | C10: DERECHOS | D10: RECARGOS | E10: IVA | F10: TOTAL
A16: ENDOSO 6 MESES | B16: 544197.5 | C16: - | D16: 5,741.28 | E16: 87,990.21 | F16: 637,928.99 | H16: =B16*H2 -> 43535.8
B17: PRIMA NETA | C17: DERECHOS | D17: RECARGOS | E17: IVA | F17: TOTAL

Sheet DESGLOSE DE RECIBOS
A2: RAZON SOCIAL | B2: RFC | C2: DIRECCION | D2: PORCENTAJE | E2: PRIMA TOTAL | F2: CUOTA | H2: CLIENTES
A3: ARENA DE JUEGOS | B3: AJU161030UF9 | C3: BOSQUE DE CIRUELOS No. 99 PISO 4 BOSQUES DE LAS LOMAS C.P.11700 DELEGACIÓN MIGUEL HIDALGO | D3: 0.010413701 | E3: =E58*D3 -> 13287.615 | F3: 1 | G3: =(E3/366)*93 -> 3376.3611
F4: 2 | G4: =(E3/366)*91 -> 3303.7512
F5: 3 | G5: =G4 -> 3303.7512
F6: 4 | G6: =G5 -> 3303.7512 | H6: 569936
F7: TOTAL | G7: =SUM(G3:G6) -> 13287.615
A8: BOUTIQUE BOWLING | B8: BBM110328PB2 | C8: BOSQUE DE CIRUELOS No. 99 PISO 4 BOSQUES DE LAS LOMAS C.P.11700 DELEGACIÓN MIGUEL HIDALGO | D8: 0.042021581 | E8: =$E$58*D8 -> 53618.456 | F8: 1 | G8: =E8/366*93 -> 13624.362
F9: 2 | G9: =E8/366*91 -> 13331.365 | H9: 119192
F10: 3 | G10: =G9 -> 13331.365
F11: 4 | G11: =G10 -> 13331.365
F12: TOTAL | G12: =SUM(G8:G11) -> 53618.456
A13: CINEMAS LUMIERE S.A. DE C.V. | B13: CLU9408151M9 | C13: AV. JAVIER BARROS SIERRA No. 540 TORRE 1 PH1 COLONIA SANTA FE C.P. 01210 DELEGACIÓN ÁLVARO OBREGÓN | D13: 0.19155136 | E13: =$E$58*D13 -> 244414.61 | F13: 1 | G13: =E13/366*93 -> 62105.351 | H13: 302649
F14: 2 | G14: =E13/366*91 -> 60769.752
F15: 3 | G15: =G14 -> 60769.752
F16: 4 | G16: =G15 -> 60769.752
F17: TOTAL | G17: =SUM(G13:G16) -> 244414.61
A18: CINEMEX MORELIA S.A DE C.V. | B18: CMO040512BX5 | C18: AV. JAVIER BARROS SIERRA No. 540 TORRE 1 PH1 COLONIA SANTA FE C.P. 01210 DELEGACIÓN ÁLVARO OBREGÓN | D18: 0.19713715 | E18: =$E$58*D18 -> 251541.93 | F18: 1 | G18: =E18/366*93 -> 63916.393
F19: 2 | G19: =E18/366*91 -> 62541.847 | H19: 302621
F20: 3 | G20: =G19 -> 62541.847
F21: 4 | G21: =G20 -> 62541.847
F22: TOTAL | G22: =SUM(G18:G21) -> 251541.93
A23: CINEMEX SAN ANTONIO S.A. DE C.V. | B23: CSA970723LT7 | C23: AV. JAVIER BARROS SIERRA No. 540 TORRE 1 PH1 COLONIA SANTA FE C.P. 01210 DELEGACIÓN ÁLVARO OBREGÓN | D23: 0.16845506 | E23: =$E$58*D23 -> 214944.32 | F23: 1 | G23: =E23/366*93 -> 54617
F24: 2 | G24: =E23/366*91 -> 53442.441 | H24: 302638
F25: 3 | G25: =G24 -> 53442.441
F26: 4 | G26: =G25 -> 53442.441
F27: TOTAL | G27: =SUM(G23:G26) -> 214944.32
A28: CINEMEX TOLUCA II S.A. DE C.V. | B28: CTI000411AA3 | C28: AV. JAVIER BARROS SIERRA No. 540 TORRE 1 PH1 COLONIA SANTA FE C.P. 01210 DELEGACIÓN ÁLVARO OBREGÓN | D28: 0.18339164 | E28: =$E$58*D28 -> 234003.02 | F28: 1 | G28: =E28/366*93 -> 59459.783
F29: 2 | G29: =E28/366*91 -> 58181.078
F30: 3 | G30: =G29 -> 58181.078 | H30: 302639
F31: 4 | G31: =G30 -> 58181.078
F32: TOTAL | G32: =SUM(G28:G31) -> 234003.02
A33: CINEMEX WTC S.A. DE C.V. | B33: CWT97121519A | C33: AV. JAVIER BARROS SIERRA No. 540 TORRE 1 PH1 COLONIA SANTA FE C.P. 01210 DELEGACIÓN ÁLVARO OBREGÓN | D33: 0.18452693 | E33: =$E$58*D33 -> 235451.61 | F33: 1 | G33: =E33/366*93 -> 59827.869
F34: 2 | G34: =E33/366*91 -> 58541.248 | H34: 569941
F35: 3 | G35: =G34 -> 58541.248
F36: 4 | G36: =G35 -> 58541.248
F37: TOTAL | G37: =SUM(G33:G36) -> 235451.61
A38: ENTRETENIMIENTO ALTERNO S.A. DE C.V. | B38: EAL030815ICA | C38: AV. JAVIER BARROS SIERRA No. 540 TORRE 1 PH1 COLONIA SANTA FE C.P. 01210 DELEGACIÓN ÁLVARO OBREGÓN | D38: 0.0001058619 | E38: =$E$58*D38 -> 135.07705 | F38: 1 | G38: =E38/366*93 -> 34.322858
F39: 2 | G39: =E38/366*91 -> 33.584732 | H39: 343424
F40: 3 | G40: =G39 -> 33.584732
F41: 4 | G41: =G40 -> 33.584732
...

Sheet Ubicaciones total (2)
A1: CONSECUTIVO | B1: SEGÚN CONTRATO DE ARRENDAMIENTO | C1: ESTADO | D1: CIUDAD O DELEGACION | E1: DIRECCION COMPLETA POR COMPLEJO | F1: CODIGO POSTAL | G1: DIRECCION COMPLETA | H1: VALOR EDIFICIOS | I1: VALOR CONTENIDOS USD | J1: EQUIPO ELECTRONICO USD | K1: INTERRUPCIÓN DE NEGOCIOS USD
A2: 1 | B2: Cinemas Lumiere S.A. de C.V. | C2: AGUASCALIENTES | D2: AGUASCALIENTES | E2: AV. INDEPENDENCIA #2351 TROJES DE ALONSO CENTRO COMERCIAL GALERIAS | F2: 20130 | G2: =CONCATENATE(E2,C2,D2,F2) -> AV. INDEPENDENCIA #2351 TROJES DE ALONSO CENTRO COMERCIAL GALERIASAGUASCALIENTESAGUASCALIENTES20130 | H2: 0 | I2: 2914531.1 | J2: 2437607.8 | K2: 1577355.4
A3: =+A2+1 -> 2 | B3: Cinemex San Antonio S.A de C.V. | C3: BAJA CALIFORNIA NORTE | D3: TIJUANA | E3: BLVD.AGUA AZUL No.7200 COL. LOMA BONITA NORTE LOCAL A-6 C.C. PLAZA LOMA BONITA TIJUANA, BAJA CALIFORNIA | F3: 22180 | G3: =CONCATENATE(E3,C3,D3,F3) -> BLVD.AGUA AZUL No.7200 COL. LOMA BONITA NORTE LOCAL A-6 C.C. PLAZA LOMA BONITA TIJUANA, BAJA CALIFORNIABAJA CALIFORNIA NORTETIJUANA22180 | H3: 0 | I3: 2210135 | J3: 1848476.5 | K3: 970304.07
A4: =+A3+1 -> 3 | B4: Cinemex Toluca II S.A de C.V. | C4: BAJA CALIFORNIA SUR | D4: LOS CABOS | E4: BOULEVARD LAZARO CARDENAS S/N LOCAL 301 Y 302 INTERIOR PLAZA PUERTO PARAISO COL. EL MEDANO CABO SAN LUCAS | F4: 23410 | G4: =CONCATENATE(E4,C4,D4,F4) -> BOULEVARD LAZARO CARDENAS S/N LOCAL 301 Y 302 INTERIOR PLAZA PUERTO PARAISO COL. EL MEDANO CABO SAN LUCASBAJA CALIFORNIA SUR LOS CABOS 23410 | H4: 0 | I4: 2914531.1 | J4: 2437607.8 | K4: 1251126.4
A5: =+A4+1 -> 4 | B5: Cinemex San Antonio S.A de C.V. | C5: BAJA CALIFORNIA NORTE | D5: TIJUANA | E5: BLVD. INSURGENTES #18015 ENTRE BLVD.MANUEL J. CLOUTHIER Y CALLE PASEO DEL PARQUE. TERCERA ETAPA RIO TIJUANA. CCMACROPLA | F5: 22110 | G5: =CONCATENATE(E5,C5,D5,F5) -> BLVD. INSURGENTES #18015 ENTRE BLVD.MANUEL J. CLOUTHIER Y CALLE PASEO DEL PARQUE. TERCERA ETAPA RIO TIJUANA. CCMACROPLABAJA CALIFORNIA NORTETIJUANA22110 | H5: 0 | I5: 4144003 | J5: 3465893.5 | K5: 1911967
A6: =+A5+1 -> 5 | B6: Cinemex San Antonio S.A de C.V. | C6: CAMPECHE | D6: CIUDAD DEL CARMEN | E6: PREDIO URBANO S/N LOCAL 35 AV.PERIFERICA NORTE X AV.CONCORDIA COL.ASA PONIENTE CD.DEL CARMEN, CAMPECHE | F6: 24170 | G6: =CONCATENATE(E6,C6,D6,F6) -> PREDIO URBANO S/N LOCAL 35 AV.PERIFERICA NORTE X AV.CONCORDIA COL.ASA PONIENTE CD.DEL CARMEN, CAMPECHECAMPECHECIUDAD DEL CARMEN24170 | H6: 0 | I6: 1885394.8 | J6: 1576875.6 | K6: 974495.44
A7: =+A6+1 -> 6 | B7: Cinemas Lumiere S.A. de C.V. | C7: CAMPECHE | D7: CIUDAD DEL CARMEN | E7: CARRETERA PUERTO REAL KM 2.5, COL. PALMIRA CIUDAD DEL CARMEN CAMPECHE | F7: 24154 | G7: =CONCATENATE(E7,C7,D7,F7) -> CARRETERA PUERTO REAL KM 2.5, COL. PALMIRA CIUDAD DEL CARMEN CAMPECHECAMPECHECIUDAD DEL CARMEN24154 | H7: 0 | I7: 2762668.7 | J7: 2310595.6 | K7: 1638130.3
A8: =+A7+1 -> 7 | B8: Cinemex Morelia S.A. de C.V. | C8: CHIHUAHUA | D8: CIUDAD DELICIAS | E8: AVE. DEL PARQUE ORIENTE #1000 LOCAL C SECTOR ORIENTE PLAZA OASIS | F8: 33000 | G8: =CONCATENATE(E8,C8,D8,F8) -> AVE. DEL PARQUE ORIENTE #1000 LOCAL C SECTOR ORIENTE PLAZA OASISCHIHUAHUACIUDAD DELICIAS33000 | H8: 0 | I8: 2210135 | J8: 1848476.5 | K8: 883682.25
A9: =+A8+1 -> 8 | B9: Cinemex Morelia S.A. de C.V. | C9: CHIHUAHUA | D9: CIUDAD DELICIAS | E9: BLVD. JOSE FUENTES MARES # 300, COL. STA. ROSA, CD. DELICIAS, CHIH. | F9: 31060 | G9: =CONCATENATE(E9,C9,D9,F9) -> BLVD. JOSE FUENTES MARES # 300, COL. STA. ROSA, CD. DELICIAS, CHIH.CHIHUAHUACIUDAD DELICIAS31060 | H9: 0 | I9: 1657601.2 | J9: 1386357.4 | K9: 718821.37
A10: =+A9+1 -> 9 | B10: Cinemas Lumiere S.A. de C.V. | C10: CHIHUAHUA | D10: CIUDAD DELICIAS | E10: BLVD. ORTIZ MENA y C. INDIANA # 3300-D, COL. LAS AGUILAS, CD DELICIAS, CHIH. | F10: 31267 | G10: =CONCATENATE(E10,C10,D10,F10) -> BLVD. ORTIZ MENA y C. INDIANA # 3300-D, COL. LAS AGUILAS, CD DELICIAS, CHIH.CHIHUAHUACIUDAD DELICIAS31267 | H10: 0 | I10: 2762668.7 | J10: 2310595.6 | K10: 1123289.4
A11: =+A10+1 -> 10 | B11: Cinemas Lumiere S.A. de C.V. | C11: CHIHUAHUA | D11: CIUDAD JUAREZ | E11: AVE.TECNOLOGICO # 1770 COL. FUENTES DEL VALLE, CD. JUAREZ, CHIH | F11: 32500 | G11: =CONCATENATE(E11,C11,D11,F11) -> AVE.TECNOLOGICO # 1770 COL. FUENTES DEL VALLE, CD. JUAREZ, CHIHCHIHUAHUACIUDAD JUAREZ32500 | H11: 0 | I11: 3867736.2 | J11: 3234833.9 | K11: 1596915.1
A12: =+A11+1 -> 11 | B12: Cinemas Lumiere S.A. de C.V. | C12: CHIHUAHUA | D12: CIUDAD JUAREZ | E12: PASEO TRIUNFO DE LA REPUBLICA # 5298, COL. SAN LORENZO, CD JUAREZ, CHIH | F12: 32320 | G12: =CONCATENATE(E12,C12,D12,F12) -> PASEO TRIUNFO DE LA REPUBLICA # 5298, COL. SAN LORENZO, CD JUAREZ, CHIHCHIHUAHUACIUDAD JUAREZ32320 | H12: 0 | I12: 2762668.7 | J12: 2310595.6 | K12: 949347.18
A13: =+A12+1 -> 12 | B13: Cinemas Lumiere S.A. de C.V. | C13: CHIHUAHUA | D13: CIUDAD JUAREZ | E13: EDUARDO SANDER`S # 1551, COL. EL BARREAL, CD. JUAREZ, CHIH | F13: 32040 | G13: =CONCATENATE(E13,C13,D13,F13) -> EDUARDO SANDER`S # 1551, COL. EL BARREAL, CD. JUAREZ, CHIHCHIHUAHUACIUDAD JUAREZ32040 | H13: 0 | I13: 1657601.2 | J13: 1386357.4 | K13: 685988.91
A14: =+A13+1 -> 13 | B14: Cinemex Morelia S.A. de C.V. | C14: COAHUILA | D14: MONCLOVA | E14: AV. HUEMAC ESQ. BRASIL, COL. ANAHUAC, MONCLOVA, COAH | F14: 27750 | G14: =CONCATENATE(E14,C14,D14,F14) -> AV. HUEMAC ESQ. BRASIL, COL. ANAHUAC, MONCLOVA, COAHCOAHUILAMONCLOVA27750 | H14: 0 | I14: 2210135 | J14: 1848476.5 | K14: 1072992.8
... A132: =+A131+1 -> 131 | B132: Cinemex San Antonio S.A de C.V. | C132: JALISCO | D132: TONALA | E132: PROLONGACION PABLO VALDEZ No. 350, COL. CAMICHINES I , TONALA JALISCO | F132: 45403 | G132: =CONCATENATE(E132,C132,D132,F132) -> PROLONGACION PABLO VALDEZ No. 350, COL. CAMICHINES I , TONALA JALISCOJALISCOTONALA45403 | H132: 0 | I132: 2762668.7 | J132: 2310595.6 | K132: 1371279.3
A133: =+A132+1 -> 132 | B133: Cinemex Toluca II S.A de C.V. | C133: CDMX | D133: ALVARO OBREGON | E133: AV. JAVIER BARRIOS SIERRA No. 540, COL. SANTA FE, DELEG. ALVARO OBREGON, MEXICO D.F. | F133: 01210 | G133: =CONCATENATE(E133,C133,D133,F133) -> AV. JAVIER BARRIOS SIERRA No. 540, COL. SANTA FE, DELEG. ALVARO OBREGON, MEXICO D.F.CDMXALVARO OBREGON01210 | H133: 0 | I133: 1256929.9 | J133: 1051250.4 | K133: 157875.25
A134: =+A133+1 -> 133 | B134: Cinemex San Antonio S.A de C.V. | C134: TAMAULIPAS | D134: TAMAULIPAS | E134: AV. FRANCISCO I. MADERO NO. 2000, ESQ. CALLE URSULA GALVAN, COL. INFONAVIT LA PAZ TAMAULIPAS | F134: 88990 | G134: =CONCATENATE(E134,C134,D134,F134) -> AV. FRANCISCO I. MADERO NO. 2000, ESQ. CALLE URSULA GALVAN, COL. INFONAVIT LA PAZ TAMAULIPASTAMAULIPASTAMAULIPAS88990 | H134: 0 | I134: 1933868.1 | J134: 1617416.9 | K134: 80334.75
A135: =+A134+1 -> 134 | B135: Cinemex Toluca II S.A de C.V. | C135: QUINTANA ROO | D135: CANCUN | E135: Supermanzana 248 manzana 11lt 111016 , esquina Av Kabah y Av De los tules S7N Region Benito Juarez 248 , cp 77519 Quintana Roo | F135: 77519 | G135: =CONCATENATE(E135,C135,D135,F135) -> Supermanzana 248 manzana 11lt 111016 , esquina Av Kabah y Av De los tules S7N Region Benito Juarez 248 , cp 77519 Quintana RooQUINTANA ROOCANCUN77519 | H135: 0 | I135: 2762668.7 | J135: 2310595.6 | K135: 1147040.5
A136: =+A135+1 -> 135 | B136: Cinemex San Antonio S.A de C.V. | C136: OAXACA | D136: OAXACA | E136: Monte Alban 1462 entre Monte Tacaña y Monte Carlo, Montoya Oaxaca de Juarez C.P. 68036 | F136: 68143 | G136: =CONCATENATE(E136,C136,D136,F136) -> Monte Alban 1462 entre Monte Tacaña y Monte Carlo, Montoya Oaxaca de Juarez C.P. 68036OAXACAOAXACA68143 | H136: 0 | I136: 3038935.6 | J136: 2541655.2 | K136: 1321681.3
A137: =+A136+1 -> 136 | B137: Teatro Polanco S.A. de C.V. | C137: TORREON | D137: COAHUILA | E137: Calzada Jose Vasconcelos 1955, L1010 Colonia Residencial Tecnologico Torreon Coahuila | F137: 27272 | G137: =CONCATENATE(E137,C137,D137,F137) -> Calzada Jose Vasconcelos 1955, L1010 Colonia Residencial Tecnologico Torreon CoahuilaTORREONCOAHUILA27272 | H137: 0 | I137: 3467064.8 | J137: 2899726.9 | K137: 1391537.6
A138: =+A137+1 -> 137 | B138: Cinemex San Antonio S.A de C.V. | C138: JALISCO | D138: PUERTO VALLARTA | E138: Av. Francisco Villa 526 esquina con Gonzalez Gallo Fraccionamiento Sauces Puerto Vallarta Jalisco | F138: 48328 | G138: =CONCATENATE(E138,C138,D138,F138) -> Av. Francisco Villa 526 esquina con Gonzalez Gallo Fraccionamiento Sauces Puerto Vallarta JaliscoJALISCOPUERTO VALLARTA48328 | H138: 0 | I138: 3591469.3 | J138: 3003774.3 | K138: 1568274
A139: =+A138+1 -> 138 | B139: Cinemex Toluca II S.A de C.V. | C139: ESTADO DE MEXICO | D139: ECATEPEC | E139: Av. Central manzana 632 numero 50 local D-01 Colonia Ciudad Azteca Ecatepec C.P. 55120 | F139: 55120 | G139: =CONCATENATE(E139,C139,D139,F139) -> Av. Central manzana 632 numero 50 local D-01 Colonia Ciudad Azteca Ecatepec C.P. 55120ESTADO DE MEXICOECATEPEC55120 | H139: 0 | I139: 3315202.4 | J139: 2772714.8 | K139: 1814866.8
A140: =+A139+1 -> 139 | B140: Cinemex Toluca II S.A de C.V. | C140: BAJA CALIFORNIA | D140: LA PAZ | E140: Blvd. Constituyentes de 1975 numero 4120 esquina calle algodón COLONIA SECTOR INALAPA municipio de la paz local SA 02 | F140: 23098 | G140: =CONCATENATE(E140,C140,D140,F140) -> Blvd. Constituyentes de 1975 numero 4120 esquina calle algodón COLONIA SECTOR INALAPA municipio de la paz local SA 02BAJA CALIFORNIALA PAZ23098 | H140: 0 | I140: 2876565.5 | J140: 2405854.8 | K140: 939567.29
A141: =+A140+1 -> 140 | B141: Cinemex Toluca II S.A de C.V. | C141: LEON | D141: LEON GUANAJUATO | E141: Blvd. Adolfo López Mateos No. 1702 Colonia La Martinica C.P. 37500 León Guanajuato | F141: 37500 | G141: =CONCATENATE(E141,C141,D141,F141) -> Blvd. Adolfo López Mateos No. 1702 Colonia La Martinica C.P. 37500 León GuanajuatoLEONLEON GUANAJUATO37500 | H141: 0 | I141: 2809204.5 | J141: 2349516.5 | K141: 1182667.2
A142: =+A141+1 -> 141 | B142: Cinemex WTC S.A. de C.V. | C142: TABASCO | D142: VILLAHERMOSA | E142: Periferico Carlos Pellicer y avenida Cesar Sandino Camara #1290 Colonia 1° de Mayo Municipio del Centro Villahermosa Tabasco C.P. 86190 | F142: 86190 | G142: =CONCATENATE(E142,C142,D142,F142) -> Periferico Carlos Pellicer y avenida Cesar Sandino Camara #1290 Colonia 1° de Mayo Municipio del Centro Villahermosa Tabasco C.P. 86190TABASCOVILLAHERMOSA86190 | H142: 0 | I142: 4333831 | J142: 3624658.7 | K142: 1633939
A143: =+A142+1 -> 142 | B143: Cinemex Morelia S.A. de C.V. | C143: CDMX | D143: CUAJIMALPA | E143: Av. Vasco de Quiroga 3800 Colonia SANTA FE CUAJIMALPA Delegacion Cuajimalpa | F143: 5348 | G143: =CONCATENATE(E143,C143,D143,F143) -> Av. Vasco de Quiroga 3800 Colonia SANTA FE CUAJIMALPA Delegacion CuajimalpaCDMXCUAJIMALPA5348 | H143: 0 | I143: 6769309.6 | J143: 5661604.4 | K143: 2638472.6
A144: =+A143+1 -> 143 | B144: Cinemas Lumiere S.A. de C.V. | C144: CDMX | D144: BENITO JUAREZ | E144: Av. División del norte 2462 piso 1 colonia Portales Benito Juarez Mexico D.F. C.P. 03300 | F144: 03300 | G144: =CONCATENATE(E144,C144,D144,F144) -> Av. División del norte 2462 piso 1 colonia Portales Benito Juarez Mexico D.F. C.P. 03300CDMXBENITO JUAREZ03300 | H144: 0 | I144: 2762668.7 | J144: 2310595.6 | K144: 1089758.3
A145: =+A144+1 -> 144 | B145: Cinemas Lumiere S.A. de C.V. | C145: CDMX | D145: CUAUHTEMOC | E145: Río Guadalquivir 104 Pb Mezzanine y piso 1 Colonia Cuauhtemoc , delegacion Cuauhtemoc D.F. C.P. 06500 | F145: 06500 | G145: =CONCATENATE(E145,C145,D145,F145) -> Río Guadalquivir 104 Pb Mezzanine y piso 1 Colonia Cuauhtemoc , delegacion Cuauhtemoc D.F. C.P. 06500CDMXCUAUHTEMOC06500 | H145: 0 | I145: 1151603.3 | J145: 963159.13 | K145: 435903.34
A146: =+A145+1 -> 145 | B146: Cinemas Lumiere S.A. de C.V. | C146: ESTADO DE MEXICO | D146: CHALCO | E146: Vicente Guerrero 25 Centro Chalco Estado de México C.P. 56600 | F146: 56600 | G146: =CONCATENATE(E146,C146,D146,F146) -> Vicente Guerrero 25 Centro Chalco Estado de México C.P. 56600ESTADO DE MEXICOCHALCO56600 | H146: 0 | I146: 2762668.7 | J146: 2310595.6 | K146: 1525661.7
A147: =+A146+1 -> 146 | B147: Cinemas Lumiere S.A. de C.V. | C147: ESTADO DE MEXICO | D147: COACALCO | E147: Via López Portillo 105 Local H Col. Villa de las flores Coacalco de Berriozabal estado de México C.P. 57700 | F147: 57700 | G147: =CONCATENATE(E147,C147,D147,F147) -> Via López Portillo 105 Local H Col. Villa de las flores Coacalco de Berriozabal estado de México C.P. 57700ESTADO DE MEXICOCOACALCO57700 | H147: 0 | I147: 3038935.6 | J147: 2541655.2 | K147: 1490035
A148: =+A147+1 -> 147 | B148: Cinemas Lumiere S.A. de C.V. | C148: ESTADO DE MEXICO | D148: CUAUTITLAN IZCALLI | E148: Av. Prolongacion Morelos s/n Esq. Ferrocarril Central Paseo Santa Maria Huerto Cuautitlan Izcalli Edo de Mexico C.P. 54820 | F148: 54800 | G148: =CONCATENATE(E148,C148,D148,F148) -> Av. Prolongacion Morelos s/n Esq. Ferrocarril Central Paseo Santa Maria Huerto Cuautitlan Izcalli Edo de Mexico C.P. 54820ESTADO DE MEXICOCUAUTITLAN IZCALLI54800 | H148: 0 | I148: 2762668.7 | J148: 2310595.6 | K148: 1066007.2
A149: =+A148+1 -> 148 | B149: Cinemas Lumiere S.A. de C.V. | C149: ESTADO DE MEXICO | D149: TEXCOCO | E149: Juarez 304 local 0 Centro , Texcoco Estado de México C.P. 56177 | F149: 56100 | G149: =CONCATENATE(E149,C149,D149,F149) -> Juarez 304 local 0 Centro , Texcoco Estado de México C.P. 56177ESTADO DE MEXICOTEXCOCO56100 | H149: 0 | I149: 2762668.7 | J149: 2310595.6 | K149: 948648.61
A150: =+A149+1 -> 149 | B150: Cinemas Lumiere S.A. de C.V. | C150: JALISCO | D150: ZAPOPAN | E150: Acueducto 6050 Col. Lomas del Bosque Zapopan Jalisco C.P. 45118 | F150: 45118 | G150: =CONCATENATE(E150,C150,D150,F150) -> Acueducto 6050 Col. Lomas del Bosque Zapopan Jalisco C.P. 45118JALISCOZAPOPAN45118 | H150: 0 | I150: 3937539.9 | J150: 3293215.2 | K150: 1547317.1
A151: =+A150+1 -> 150 | B151: Cinemas Lumiere S.A. de C.V. | C151: CDMX | D151: TLALPAN | E151: Av. Prolongacion Division del norte 4515 Col. Residencial Chimali , Tlalpan Distrito Federal C.P. 14370 | F151: 14370 | G151: =CONCATENATE(E151,C151,D151,F151) -> Av. Prolongacion Division del norte 4515 Col. Residencial Chimali , Tlalpan Distrito Federal C.P. 14370CDMXTLALPAN14370 | H151: 0 | I151: 2762668.7 | J151: 2310595.6 | K151: 1080677
A152: =+A151+1 -> 151 | B152: Cinemas Lumiere S.A. de C.V. | C152: CDMX | D152: TLALPAN | E152: Calzada de Tlalpan 4085 Bosques de Tetlameya Coyoacán D.F. C.P. 04730 | F152: 04730 | G152: =CONCATENATE(E152,C152,D152,F152) -> Calzada de Tlalpan 4085 Bosques de Tetlameya Coyoacán D.F. C.P. 04730CDMXTLALPAN04730 | H152: 0 | I152: 2210135 | J152: 1848476.5 | K152: 871806.68
A153: =+A152+1 -> 152 | B153: Cinemas Lumiere S.A. de C.V. | C153: PUEBLA | D153: PUEBLA | E153: Boulevard Heroes del 5 de mayo 3126 Zona Dorada huexotitla Puebla Puebla C.P. 72420 | F153: 72534 | G153: =CONCATENATE(E153,C153,D153,F153) -> Boulevard Heroes del 5 de mayo 3126 Zona Dorada huexotitla Puebla Puebla C.P. 72420PUEBLAPUEBLA72534 | H153: 0 | I153: 2762668.7 | J153: 2310595.6 | K153: 1108619.5
A154: =+A153+1 -> 153 | B154: Cinemas Lumiere S.A. de C.V. | C154: ESTADO DE MEXICO | D154: IXTAPALUCA | E154: Carretera federal Mexico-Cuautla , Plaza comercial el cortijo Km 37 Mz 1 Colonia Santa Barbara Ixtapaluca Estado de Mexico C.P. 56538 | F154: 56538 | G154: =CONCATENATE(E154,C154,D154,F154) -> Carretera federal Mexico-Cuautla , Plaza comercial el cortijo Km 37 Mz 1 Colonia Santa Barbara Ixtapaluca Estado de Mexico C.P. 56538ESTADO DE MEXICOIXTAPALUCA56538 | H154: 0 | I154: 3315202.4 | J154: 2772714.8 | K154: 1282561.7
A155: =+A154+1 -> 154 | B155: Cinemas Lumiere S.A. de C.V. | C155: ESTADO DE MEXICO | D155: TEXCOCO | E155: Carretera federal México-Texcoco Km 30.5 Colonia Santiago Cuautlalpan Plaza comercial Puerta Texcoco , Texcoco Estado de México C.P. 56370 | F155: 56255 | G155: =CONCATENATE(E155,C155,D155,F155) -> Carretera federal México-Texcoco Km 30.5 Colonia Santiago Cuautlalpan Plaza comercial Puerta Texcoco , Texcoco Estado de México C.P. 56370ESTADO DE MEXICOTEXCOCO56255 | H155: 0 | I155: 3038935.6 | J155: 2541655.2 | K155: 1114208.1
A156: =+A155+1 -> 155 | B156: Cinemas Lumiere S.A. de C.V. | C156: PACHUCA | D156: HIDALGO | E156: Blvd. Luis Donaldo Colosio Local J02 Mz 1 Fracc 1 No 2009 Ex Hacienda de Coscotitlan Plaza Comercial Pachuca de Soto Hidalgo C.P. 42064 | F156: 42064 | G156: =CONCATENATE(E156,C156,D156,F156) -> Blvd. Luis Donaldo Colosio Local J02 Mz 1 Fracc 1 No 2009 Ex Hacienda de Coscotitlan Plaza Comercial Pachuca de Soto Hidalgo C.P. 42064PACHUCAHIDALGO42064 | H156: 0 | I156: 2762668.7 | J156: 2310595.6 | K156: 1026887.7
A157: =+A156+1 -> 156 | B157: Cinemas Lumiere S.A. de C.V. | C157: ESTADO DE MEXICO | D157: CUAUTITLAN | E157: Carretera Cuautitlan Melchor Ocampo 29 esq libramiento la Joya colonia VILLAS DE CUAUTITLAN Cuautitlan Estado de México C.P. 54800 | F157: 54857 | G157: =CONCATENATE(E157,C157,D157,F157) -> Carretera Cuautitlan Melchor Ocampo 29 esq libramiento la Joya colonia VILLAS DE CUAUTITLAN Cuautitlan Estado de México C.P. 54800ESTADO DE MEXICOCUAUTITLAN54857 | H157: 0 | I157: 2762668.7 | J157: 2310595.6 | K157: 1106523.9
...

Sheet COTIZACIÓN M.N.
B4: GRUPO MEXICANO DE SEGUROS, S.A.DE C.V.
B5: COTIZACIÓN MÚLTIPLE EMPRESARIAL
B7: DATOS GENERALES
B8: Asegurado | C8: OPERADORA DE CINEMAS SA DE CV
B9: R.F.C.: | C9: PENDIENTE
B10: Dirección Fiscal:
B11: Dirección del Riesgo: | C11: =C10 -> 0 | F11: C.P. | G11: 77500
B12: Giro: | C12: HOTEL CON ESTACIONAMIENTO, LOCALES COMERCIALES, SERVICIOS RECREATIVOS Y LO RELACIONADO AL GIRO DEL ASEGURADO | F12: No. Días | G12: =D16-C16 -> 366
F13: Zona TEV AMIS | G13: A
B14: Tipos Constructivos: | C14: CONSTRUCCION MACIZA, MUROS, TECHOS Y ENTREPISOS DE CONCRETO, CONSTA DE P.B. Y 12 PISOS ALTOS | F14: Coaseguro T.E.V. | G14: 0
B15: Protecciones: | C15: Minimo debera tener extintores suficientes uno cada 15 Mts. Del otro, con recarga vigente, libres de obstaculos de acuerdo a la Norma Oficial Mexicana, vigilancia las 24 Hrs. Y los 365 días al año, en caso de que algunas de las medidas anteriores, no exista y/o se encuentre fuera de servicio, GMX Seguros quedara liberada de cualquier Responsabilidad en caso de siniestro Indemnizable. | F15: % de Remoción Esc. | G15: 0.2
B16: Vigencia | C16: 45107 | D16: 45473 | F16: Inflación | G16: 0
B17: Siniestralidad | C17: SIN SINIESTROS EN LOS ULTIMOS 5 AÑOS | F17: Zona F.H.M. ALFA | G17: A1PS
B18: Moneda: | C18: DOLARES | D18: USD | F18: Coaseguro F.H.M. | G18: 0
B19: Agente: | C19: MARSH | F19: Coaseguro Convenido para Edificio y/o Contenidos | G19: 1
F20: =F97 -> 1088395.2 | H20: 1088395 | N20: ='Hoja Contable'!N413 -> 0.080011672
B21: DETALLE DE COBERTURAS Y PRIMAS
B22: Sección | C22: Ramo | D22: valores al 100% | E22: Cuota al 100% | F22: Prima al 100% | G22: Comisión %
B24: EDIFICIO | C24: Incendio y/o Rayo | D24: ='Ubicaciones total (2)'!H366 -> 155549.7 | E24: 0.236781 | F24: =(D24*E24/1000)/365*$G$12 -> 36.932121 | G24: 0.25 | H24: =G24*F24 -> 9.2330302
C25: Extensión de Cubierta | D25: =D24 -> 155549.7 | E25: =+E24*10% -> 0.0236781 | F25: =(D25*E25/1000)/365*$G$12 -> 3.6932121 | G25: =$G$24 -> 0.25 | H25: =G25*F25 -> 0.92330302
B26: 1 | C26: Todo Riesgo | D26: =D24*B26 -> 155549.7 | E26: =(E24*20%)*B26 -> 0.0473562 | F26: =(D26*E26/1000)/365*$G$12 -> 7.3864242 | G26: =$G$24 -> 0.25 | H26: =G26*F26 -> 1.846606
B27: =G16 -> 0 | C27: Inflación | D27: =D24*B27 -> 0 | E27: =(E24+E25+E26)*35% -> 0.10773536 | F27: =(D27*E27/1000)/365*$G$12 -> 0 | G27: =G24 -> 0.25 | H27: =G27*F27 -> 0
B28: =100%-G18 -> 1 | C28: F.H.M. | D28: =(D24/G19)*B28 -> 155549.7 | E28: 0.25 | F28: =(D24*E28/1000)/365*$G$12 -> 38.993966 | G28: 0.05 | H28: =G28*F28 -> 1.9496983
B29: =B27 -> 0 | C29: Inflación | D29: =(D28)*B27 -> 0 | E29: =E28*35% -> 0.0875 | F29: =(D29*E29/1000)/365*$G$12 -> 0 | G29: =+G28 -> 0.05 | H29: =G29*F29 -> 0
B30: =100%-G14 -> 1 | C30: T.E.V. | D30: =(D24/G19)*B30 -> 155549.7 | E30: 0.4 | F30: =(D30*E30/1000)/365*$G$12 -> 62.390345 | G30: =G28 -> 0.05 | H30: =G30*F30 -> 3.1195173
B31: =B27 -> 0 | C31: =C29 -> Inflación | D31: =D30*B27 -> 0 | E31: =E30*35% -> 0.14 | F31: =(D31*E31/1000)/365*$G$12 -> 0 | G31: =G28 -> 0.05 | H31: =G31*F31 -> 0
B33: CONTENIDOS | C33: Incendio | D33: ='Ubicaciones total (2)'!I366 -> 8.6921645e+08 | E33: =E24 -> 0.236781 | F33: =(D33*E33/1000)/365*$G$12 -> 206377.81 | G33: =$G$24 -> 0.25 | H33: =G33*F33 -> 51594.454
C34: =C25 -> Extensión de Cubierta | D34: =D33 -> 8.6921645e+08 | E34: =E25 -> 0.0236781 | F34: =(D34*E34/1000)/365*$G$12 -> 20637.781 | G34: =$G$24 -> 0.25 | H34: =G34*F34 -> 5159.4454
C35: Todo Riesgo | D35: =D33*B26 -> 8.6921645e+08 | E35: =+E26 -> 0.0473562 | F35: =(D35*E35/1000)/365*$G$12 -> 41275.563 | G35: =$G$24 -> 0.25 | H35: =G35*F35 -> 10318.891
B36: =G16 -> 0 | C36: =C27 -> Inflación | D36: =D33*B36 -> 0 | E36: =(E33+E34+E35)*35% -> 0.10773536 | F36: =(D36*E36/1000)/365*$G$12 -> 0 | G36: =G24 -> 0.25 | H36: =G36*F36 -> 0
B37: =100%-G18 -> 1 | C37: =C28 -> F.H.M. | D37: =(D33/G19)*B37 -> 8.6921645e+08 | E37: =E28 -> 0.25 | F37: =(D33*E37/1000)/365*$G$12 -> 217899.47 | G37: =$G$28 -> 0.05 | H37: =G37*F37 -> 10894.973
B38: =B36 -> 0 | C38: =C29 -> Inflación | D38: =(D33/G19)*B36 -> 0 | E38: =E37*35% -> 0.0875 | F38: =(D38*E38/1000)/365*$G$12 -> 0 | G38: =G28 -> 0.05 | H38: =G38*F38 -> 0
B39: =B30 -> 1 | C39: =C30 -> T.E.V. | D39: =(D33/G19)*B30 -> 8.6921645e+08 | E39: =E30*0.5 -> 0.2 | F39: =(D39*E39/1000)/365*$G$12 -> 174319.57 | G39: =$G$28 -> 0.05 | H39: =G39*F39 -> 8715.9787
B40: =B36 -> 0 | C40: =C29 -> Inflación | D40: =D39*B36 -> 0 | E40: =E39*35% -> 0.07 | F40: =(D40*E40/1000)/365*$G$12 -> 0 | G40: =$G$28 -> 0.05 | H40: =G40*F40 -> 0
B42: PERDIDAS CONSECUENCIALES | D42: ='Ubicaciones total (2)'!K366 -> 3.2429902e+08 | E42: =(E24+E25+E26)*80% -> 0.24625224 | F42: =(D42*E42/1000)/365*$G$12 -> 80078.153 | G42: =G24 -> 0.25 | H42: =G42*F42 -> 20019.538
B43: FHM ( Gastos Fijos y Salarios) Opera como Sublimite | D43: =D42 -> 3.2429902e+08 | E43: =E28*80% -> 0.2 | F43: =(D43*E43/1000)/365*$G$12 -> 65037.502 | G43: =$G$28 -> 0.05 | H43: =G43*F43 -> 3251.8751 | K43: 0.8 | M43: 0.7
B44: TEV ( Gastos Fijos y Salarios) Opera como Sublimite | D44: =+D43 -> 3.2429902e+08 | E44: =(E30*B39)*80% -> 0.32 | F44: =(D44*E44/1000)/365*$G$12 -> 104060 | G44: =$G$28 -> 0.05 | H44: =G44*F44 -> 5203.0002 | K44: 1 | M44: 0.64
B46: VALORES TOTALES | D46: =SUM(D24+D33+D42+D27+D36) -> 1.193671e+09
B47: LIMITE MÁXIMO DE RESPONSABILIDAD | D47: 20000000
D49: DETALLE DE PRIMAS
...

Sheet HOJA PRIMER RIESGO
P1: SUSCRIPTOR | Q1: CLAVESUSCRIPTOR | R1: NumeroDeUbicaciones | S1: 3 | T1: =VLOOKUP(S1,S2:T5,2) -> TRIMESTRAL | U1: =IF(F13="NACIONAL",1,2) -> 2 | V1: =F13 -> DÓLARES
P2: DULCE HUERTA | Q2: DHUERTA | R2: 364 | S2: 1 | T2: CONTADO | U2: 0 | V2: 0
S3: 2 | T3: SEMESTRAL | U3: 0.042 | V3: 0.014
S4: 3 | T4: TRIMESTRAL | U4: 0.064 | V4: 0.0211
A5: HOJA CONTABLE | S5: 4 | T5: MENSUAL | U5: 0.077 | V5: 0.0258
A7: RAMO COMERCIAL | C7: 20 - SME 1ER RIESGO - ESPARCIMIENTO | K7: =MID(C7,1,2)*1 -> 20 | L7: POLIZA A PRIMER RIESGO | S7: Recargo Forma de Pago: | U7: =VLOOKUP(S1,S2:V5,U1+2) -> 0.0211
A8: GIRO | C8: 0590-ESPECTÁCULOS PÚBLICOS, CINES, TEATROS, PARQUES DE DIVERSIÓN, CASINOS Y/O SIMILARES | F8: SUBGIRO | G8: 0590.05-Cines | L8: =Hoja3!A8
A9: ASEGURADO | C9: OPERADORA DE CINEMAS SA DE CV | J9: COD. ASEG. | K9: 0 | L9: TIPO DE MOVIMIENTO | N9: RENOVACION | S9: Factor Prorrata: | U9: =IF(H14="DIRECTA",1,J15/I15) -> 1
A10: DIRECCIÓN FISCAL | C10: JAVIER BARROS SIERRA 540 TORRE 1 PH1 COL SANTA FE ALVARO OBREGON CDMX CP 01210 | L10: TIPO DE PÓLIZA | N10: TODO RIESGO
A11: DIRECCIÓN DEL RIESGO | C11: =C10 -> JAVIER BARROS SIERRA 540 TORRE 1 PH1 COL SANTA FE ALVARO OBREGON CDMX CP 01210 | L11: ZONA TEV | M11: ='COTIZACIÓN M.N.'!G13 -> A | N11: ZONA F.H.M. | O11: ='COTIZACIÓN M.N.'!G17 -> A1PS
A12: VIG. INICIO | C12: 45107 | D12: T. DE RIESGO: | F12: ORDINARIO | G12: AGENTE | H12: MARSH | K12: 1 | L12: REM. ESC. | M12: ='COTIZACIÓN M.N.'!G15 -> 0.2 | N12: Indice Variable | O12: ='COTIZACIÓN M.N.'!G16 -> 0
A13: VIG. FINAL | C13: 45473 | D13: MONEDA | F13: DÓLARES | G13: R.F.C. | H13: OCI970818KX9 | J13: DÍAS DE VIGENCIA | N13: Coaseguro FHM | O13: =100%-'COTIZACIÓN M.N.'!G18 -> 1
A14: PÓLIZA | C14: POLIZA NUEVA | D14: F. PAGO | G14: CALCULO | H14: DIRECTA | K14: IVA | N14: Coaseguro TEV | O14: =100%-'COTIZACIÓN M.N.'!G14 -> 1
C15: 1 | I15: 365 | J15: =C13-C12 -> 366 | K15: 0.16
A16: COD. RAMO TECNICO | B16: SECCIÓN / COB. | C16: SECCIÓN / COBERTURA | D16: S/N | E16: Sublimite | F16: SUMA ASEGURADA | G16: CUOTAS | H16: PRIMA | I16: METODO DE CALCULO | J16: REC. PAGO FRACC. | K16: IVA | L16: PRIMA TOTAL | M16: COM. % | N16: COMISIÓN | O16: COMISIÓN TOTAL | P16: FILTRO
A17: 902 | B17: 001 | C17: INCENDIO EDIFICIO | D17: ='Ramo Comercial'!C121 -> INCLUIDO | F17: 20000000 | G17: ='COTIZACIÓN M.N.'!E24+'COTIZACIÓN M.N.'!E25+'COTIZACIÓN M.N.'!E26 -> 0.3078153 | M17: 0.25 | P17: =IF(Q17=1,"SI","NO") -> SI | Q17: =IF(D17="INCLUIDO",IF(F17<>0,1,0),0) -> 1 | T17: =G17 -> 0.3078153
A18: INCENDIO | B18: 001 | C18: COBERTURA BÁSICA | D18: =$D$17 -> INCLUIDO | E18: Adicional | F18: =$F$17*S18 -> 20000000 | G18: =V18 -> 0.24625224 | H18: 0 | I18: %o Al Millar | J18: =H18*$U$7 -> 0 | K18: =(H18+J18)*$K$15 -> 0 | L18: =ROUND(H18+J18+K18,2) -> 0 | M18: =$M$17 -> 0.25 | N18: =H18*M18 -> 0 | O18: =N18 -> 0 | P18: =IF(Q18=1,"SI","NO") -> SI | Q18: =IF(D18="INCLUIDO",IF(F18<>0,1,0),0) -> 1 | R18: =IF(I18="%o Al Millar",1000,IF(I18="% Al Porciento",100,IF(I18="$ Prima",G18))) -> 1000 | S18: =IF(E18="Excluido",0,IF(D18="NO APLICA",0,1)) -> 1 | T18: 0.8 | U18: =IF(E18="Excluido",0,T17*T18) -> 0.24625224 | V18: =IF(F17=0,0,(U23-U22-U20)+(T17-U23)) -> 0.24625224
A19: INCENDIO | C19: =$O$12 -> 0 | D19: =$D$17 -> INCLUIDO | E19: Adicional | F19: =(F18*$O$12)*S19 -> 0 | G19: =G18*0.35 -> 0.086188284 | H19: =(IF(I19="$ Prima",G19,G19*F19/R19))*$U$9 -> 0 | I19: %o Al Millar | J19: =H19*$U$7 -> 0 | K19: =(H19+J19)*$K$15 -> 0 | L19: =ROUND(H19+J19+K19,2) -> 0 | M19: =$M$17 -> 0.25 | N19: =H19*M19 -> 0 | O19: =N19 -> 0 | P19: =IF(Q19=1,"SI","NO") -> NO | Q19: =IF(D19="INCLUIDO",IF(F19<>0,1,0),0) -> 0 | R19: =IF(I19="%o Al Millar",1000,IF(I19="% Al Porciento",100,IF(I19="$ Prima",G19))) -> 1000 | S19: =IF(E19="Excluido",0,IF(D19="NO APLICA",0,1)) -> 1
A20: INCENDIO | B20: 002 | C20: EXTENSIÓN DE CUBIERTA (SIN HURACÁN Y GRANIZO) | D20: =$D$17 -> INCLUIDO | E20: Sublimite | F20: 0 | G20: =V20 -> 0.03078153 | H20: =(((IF(I20="$ Prima",G20,G20*F20/R20))*$U$9)/365)*$J$15 -> 0 | I20: %o Al Millar | J20: =H20*$U$7 -> 0 | K20: =(H20+J20)*$K$15 -> 0 | L20: =ROUND(H20+J20+K20,2) -> 0 | M20: =$M$17 -> 0.25 | N20: =H20*M20 -> 0 | O20: =N20 -> 0 | P20: =IF(Q20=1,"SI","NO") -> NO | Q20: =IF(D20="INCLUIDO",IF(F20<>0,1,0),0) -> 0 | R20: =IF(I20="%o Al Millar",1000,IF(I20="% Al Porciento",100,IF(I20="$ Prima",G20))) -> 1000 | S20: =IF(E20="Excluido",0,IF(D20="NO APLICA",0,1)) -> 1 | T20: 0.1 | U20: =IF(E20="Excluido",0,T17*T20) -> 0.03078153 | V20: =IF(F$17=0,0,U20) -> 0.03078153
A21: INCENDIO | C21: =$O$12 -> 0 | D21: =$D$17 -> INCLUIDO | E21: =E20 -> Sublimite | F21: =(F20*$O$12)*S21 -> 0 | G21: =G20*0.35 -> 0.010773536 | H21: =(IF(I21="$ Prima",G21,G21*F21/R21))*$U$9 -> 0 | I21: %o Al Millar | J21: =H21*$U$7 -> 0 | K21: =(H21+J21)*$K$15 -> 0 | L21: =ROUND(H21+J21+K21,2) -> 0 | M21: =$M$17 -> 0.25 | N21: =H21*M21 -> 0 | O21: =N21 -> 0 | P21: =IF(Q21=1,"SI","NO") -> NO | Q21: =IF(D21="INCLUIDO",IF(F21<>0,1,0),0) -> 0 | R21: =IF(I21="%o Al Millar",1000,IF(I21="% Al Porciento",100,IF(I21="$ Prima",G21))) -> 1000 | S21: =IF(E21="Excluido",0,IF(D21="NO APLICA",0,1)) -> 1
A22: INCENDIO | B22: 012 | C22: TODO RIESGO | D22: =$D$17 -> INCLUIDO | E22: Sublimite | F22: 0 | G22: =V22 -> 0.03078153 | H22: =(((IF(I22="$ Prima",G22,G22*F22/R22))*$U$9)/365)*$J$15 -> 0 | I22: %o Al Millar | J22: =H22*$U$7 -> 0 | K22: =(H22+J22)*$K$15 -> 0 | L22: =ROUND(H22+J22+K22,2) -> 0 | M22: =$M$17 -> 0.25 | N22: =H22*M22 -> 0 | O22: =N22 -> 0 | P22: =IF(Q22=1,"SI","NO") -> NO | Q22: =IF(D22="INCLUIDO",IF(F22<>0,1,0),0) -> 0 | R22: =IF(I22="%o Al Millar",1000,IF(I22="% Al Porciento",100,IF(I22="$ Prima",G22))) -> 1000 | S22: =IF(E22="Excluido",0,IF(D22="NO APLICA",0,1)) -> 1 | T22: 0.1 | U22: =IF(E22="Excluido",0,T17*T22) -> 0.03078153 | V22: =IF(F$17=0,0,U22) -> 0.03078153
A23: INCENDIO | C23: =$O$12 -> 0 | D23: =$D$17 -> INCLUIDO | E23: =E22 -> Sublimite | F23: =(F22*$O$12)*S23 -> 0 | G23: =G22*0.35 -> 0.010773536 | H23: =(IF(I23="$ Prima",G23,G23*F23/R23))*$U$9 -> 0 | I23: %o Al Millar | J23: =H23*$U$7 -> 0 | K23: =(H23+J23)*$K$15 -> 0 | L23: =ROUND(H23+J23+K23,2) -> 0 | M23: =$M$17 -> 0.25 | N23: =H23*M23 -> 0 | O23: =N23 -> 0 | P23: =IF(Q23=1,"SI","NO") -> NO | Q23: =IF(D23="INCLUIDO",IF(F23<>0,1,0),0) -> 0 | R23: =IF(I23="%o Al Millar",1000,IF(I23="% Al Porciento",100,IF(I23="$ Prima",G23))) -> 1000 | S23: =IF(E23="Excluido",0,IF(D23="NO APLICA",0,1)) -> 1 | T23: =SUM(T18:T22) -> 1 | U23: =SUM(U18:U22) -> 0.3078153 | V23: =SUM(V18:V22) -> 0.3078153
A24: INCENDIO | B24: 280 | C24: MEJORAS Y ADAPTACIONES | D24: =$D$17 -> INCLUIDO | E24: Sublimite | F24: 0 | G24: 0 | H24: =(IF(I24="$ Prima",G24,G24*F24/R24))*$U$9 -> 0 | I24: %o Al Millar | J24: =H24*$U$7 -> 0 | K24: =(H24+J24)*$K$15 -> 0 | L24: =ROUND(H24+J24+K24,2) -> 0 | M24: =$M$17 -> 0.25 | N24: =H24*M24 -> 0 | O24: =N24 -> 0 | P24: =IF(Q24=1,"SI","NO") -> NO | Q24: =IF(D24="INCLUIDO",IF(F24<>0,1,0),0) -> 0 | R24: =IF(I24="%o Al Millar",1000,IF(I24="% Al Porciento",100,IF(I24="$ Prima",G24))) -> 1000 | S24: =IF(E24="Excluido",0,IF(D24="NO APLICA",0,1)) -> 1
A25: INCENDIO | C25: =$O$12 -> 0 | D25: =$D$17 -> INCLUIDO | E25: =E24 -> Sublimite | F25: =(F24*$O$12)*S25 -> 0 | G25: =G24*0.35 -> 0 | H25: =(IF(I25="$ Prima",G25,G25*F25/R25))*$U$9 -> 0 | I25: %o Al Millar | J25: =H25*$U$7 -> 0 | K25: =(H25+J25)*$K$15 -> 0 | L25: =ROUND(H25+J25+K25,2) -> 0 | M25: =$M$17 -> 0.25 | N25: =H25*M25 -> 0 | O25: =N25 -> 0 | P25: =IF(Q25=1,"SI","NO") -> NO | Q25: =IF(D25="INCLUIDO",IF(F25<>0,1,0),0) -> 0 | R25: =IF(I25="%o Al Millar",1000,IF(I25="% Al Porciento",100,IF(I25="$ Prima",G25))) -> 1000 | S25: =IF(E25="Excluido",0,IF(D25="NO APLICA",0,1)) -> 1
A26: INCENDIO | B26: 004 | C26: INCISOS CONOCIDOS | D26: =$D$17 -> INCLUIDO | E26: Sublimite | F26: 0 | G26: ='COTIZACIÓN M.N.'!E67*50% -> 0.0011 | H26: =(IF(I26="$ Prima",G26,G26*F26/R26))*$U$9 -> 0 | I26: %o Al Millar | J26: =H26*$U$7 -> 0 | K26: =(H26+J26)*$K$15 -> 0 | L26: =ROUND(H26+J26+K26,2) -> 0 | M26: =$M$17 -> 0.25 | N26: =H26*M26 -> 0 | O26: =N26 -> 0 | P26: =IF(Q26=1,"SI","NO") -> NO | Q26: =IF(D26="INCLUIDO",IF(F26<>0,1,0),0) -> 0 | R26: =IF(I26="%o Al Millar",1000,IF(I26="% Al Porciento",100,IF(I26="$ Prima",G26))) -> 1000 | S26: =IF(E26="Excluido",0,IF(D26="NO APLICA",0,1)) -> 1
A27: INCENDIO | B27: 005 | C27: INCISOS NO CONOCIDOS | D27: =$D$17 -> INCLUIDO | E27: Sublimite | F27: 0 | G27: =G26 -> 0.0011 | H27: =(IF(I27="$ Prima",G27,G27*F27/R27))*$U$9 -> 0 | I27: %o Al Millar | J27: =H27*$U$7 -> 0 | K27: =(H27+J27)*$K$15 -> 0 | L27: =ROUND(H27+J27+K27,2) -> 0 | M27: =$M$17 -> 0.25 | N27: =H27*M27 -> 0 | O27: =N27 -> 0 | P27: =IF(Q27=1,"SI","NO") -> NO | Q27: =IF(D27="INCLUIDO",IF(F27<>0,1,0),0) -> 0 | R27: =IF(I27="%o Al Millar",1000,IF(I27="% Al Porciento",100,IF(I27="$ Prima",G27))) -> 1000 | S27: =IF(E27="Excluido",0,IF(D27="NO APLICA",0,1)) -> 1
A28: 903 | B28: 1 | C28: HIDROMETEOROLOGICO EDIFICIO | D28: =$D$17 -> INCLUIDO | M28: 0.05 | P28: =IF(Q28=1,"SI","NO") -> SI | Q28: =IF(D28="INCLUIDO",IF(F29<>0,1,0),0) -> 1
A29: FHM | B29: 040 | C29: RIESGOS HIDROMETEOROLÓGICOS | D29: =$D$17 -> INCLUIDO | E29: Sublimite | F29: =$F$17*S29 -> 20000000 | G29: ='COTIZACIÓN M.N.'!E28 -> 0.25 | H29: 0 | I29: %o Al Millar | J29: =H29*$U$7 -> 0 | K29: =(H29+J29)*$K$15 -> 0 | L29: =ROUND(H29+J29+K29,2) -> 0 | M29: =$M$28 -> 0.05 | N29: =H29*M29 -> 0 | O29: =N29 -> 0 | P29: =IF(Q29=1,"SI","NO") -> SI | Q29: =IF(D29="INCLUIDO",IF(F29<>0,1,0),0) -> 1 | R29: =IF(I29="%o Al Millar",1000,IF(I29="% Al Porciento",100,IF(I29="$ Prima",G29))) -> 1000 | S29: =IF(E29="Excluido",0,IF(D29="NO APLICA",0,1)) -> 1
A30: FHM | C30: =$O$12 -> 0 | D30: =$D$17 -> INCLUIDO | E30: =E29 -> Sublimite | F30: =(F29*$O$12)*S30 -> 0 | G30: =G29*0.35 -> 0.0875 | H30: =((IF(I30="$ Prima",G30,G30*F30/R30))*$U$9)*O13 -> 0 | I30: %o Al Millar | J30: =H30*$U$7 -> 0 | K30: =(H30+J30)*$K$15 -> 0 | L30: =ROUND(H30+J30+K30,2) -> 0 | M30: =$M$28 -> 0.05 | N30: =H30*M30 -> 0 | O30: =N30 -> 0 | P30: =IF(Q30=1,"SI","NO") -> NO | Q30: =IF(D30="INCLUIDO",IF(F30<>0,1,0),0) -> 0 | R30: =IF(I30="%o Al Millar",1000,IF(I30="% Al Porciento",100,IF(I30="$ Prima",G30))) -> 1000 | S30: =IF(E30="Excluido",0,IF(D30="NO APLICA",0,1)) -> 1
A31: 904 | B31: 1 | C31: TERREMOTO EDIFICIO | D31: =$D$17 -> INCLUIDO | M31: 0.05 | P31: =IF(Q31=1,"SI","NO") -> SI | Q31: =IF(D31="INCLUIDO",IF(F32<>0,1,0),0) -> 1
A32: TEV | B32: 055 | C32: TERREMOTO Y ERUPCIÓN VOLCÁNICA | D32: =$D$17 -> INCLUIDO | E32: Sublimite | F32: =F17 -> 20000000 | G32: ='COTIZACIÓN M.N.'!E30 -> 0.4 | H32: 0 | I32: %o Al Millar | J32: =H32*$U$7 -> 0 | K32: =(H32+J32)*$K$15 -> 0 | L32: =ROUND(H32+J32+K32,2) -> 0 | M32: =$M$31 -> 0.05 | N32: =H32*M32 -> 0 | O32: =N32 -> 0 | P32: =IF(Q32=1,"SI","NO") -> SI | Q32: =IF(D32="INCLUIDO",IF(F32<>0,1,0),0) -> 1 | R32: =IF(I32="%o Al Millar",1000,IF(I32="% Al Porciento",100,IF(I32="$ Prima",G32))) -> 1000 | S32: =IF(E32="Excluido",0,IF(D32="NO APLICA",0,1)) -> 1
A33: TEV | C33: =$O$12 -> 0 | D33: =$D$17 -> INCLUIDO | E33: =E32 -> Sublimite | F33: =(F32*$O$12)*S33 -> 0 | G33: =G32*0.35 -> 0.14 | H33: =((IF(I33="$ Prima",G33,G33*F33/R33))*$U$9)*O14 -> 0 | I33: %o Al Millar | J33: =H33*$U$7 -> 0 | K33: =(H33+J33)*$K$15 -> 0 | L33: =ROUND(H33+J33+K33,2) -> 0 | M33: =$M$31 -> 0.05 | N33: =H33*M33 -> 0 | O33: =N33 -> 0 | P33: =IF(Q33=1,"SI","NO") -> NO | Q33: =IF(D33="INCLUIDO",IF(F33<>0,1,0),0) -> 0 | R33: =IF(I33="%o Al Millar",1000,IF(I33="% Al Porciento",100,IF(I33="$ Prima",G33))) -> 1000 | S33: =IF(E33="Excluido",0,IF(D33="NO APLICA",0,1)) -> 1
A34: 902 | B34: 001 | C34: INCENDIO EDIFICIO - REM ESC. | D34: =$D$17 -> INCLUIDO | F34: 0 | M34: 0.25 | P34: =IF(Q34=1,"SI","NO") -> NO | Q34: =IF(D34="INCLUIDO",IF(F35<>0,1,0),0) -> 0
A35: INCENDIO | B35: 011 | C35: REMOCIÓN DE ESCOMBROS INCENDIO | D35: =$D$17 -> INCLUIDO | E35: Sublimite | F35: =F34*S35 -> 0 | G35: ='COTIZACIÓN M.N.'!E61*75% -> 0.041836148 | H35: =(((IF(I35="$ Prima",G35,G35*F35/R35))*$U$9)/365)*$J$15 -> 0 | I35: %o Al Millar | J35: =H35*$U$7 -> 0 | K35: =(H35+J35)*$K$15 -> 0 | L35: =ROUND(H35+J35+K35,2) -> 0 | M35: =M34 -> 0.25 | N35: =H35*M35 -> 0 | O35: =N35 -> 0 | P35: =IF(Q35=1,"SI","NO") -> NO | Q35: =IF(D35="INCLUIDO",IF(F35<>0,1,0),0) -> 0 | R35: =IF(I35="%o Al Millar",1000,IF(I35="% Al Porciento",100,IF(I35="$ Prima",G35))) -> 1000 | S35: =IF(E35="Excluido",0,IF(D35="NO APLICA",0,1)) -> 1
A36: 903 | B36: 1 | C36: HIDROMETEOROLOGICO EDIFICIO | D36: =$D$17 -> INCLUIDO | M36: =M28 -> 0.05 | P36: =IF(Q36=1,"SI","NO") -> NO | Q36: =IF(D36="INCLUIDO",IF(F37<>0,1,0),0) -> 0
A37: FHM | B37: 038 | C37: REMOCIÓN DE ESCOMBROS FENÓMENOS HIDROMETEOROLÓGICOS | D37: =$D$17 -> INCLUIDO | E37: Sublimite | F37: 0 | G37: ='COTIZACIÓN M.N.'!E61*25% -> 0.013945383 | H37: =(((IF(I37="$ Prima",G37,G37*F37/R37))*$U$9)/365)*$J$15 -> 0 | I37: %o Al Millar | J37: =H37*$U$7 -> 0 | K37: =(H37+J37)*$K$15 -> 0 | L37: =ROUND(H37+J37+K37,2) -> 0 | M37: =M36 -> 0.05 | N37: =H37*M37 -> 0 | O37: =N37 -> 0 | P37: =IF(Q37=1,"SI","NO") -> NO | Q37: =IF(D37="INCLUIDO",IF(F37<>0,1,0),0) -> 0 | R37: =IF(I37="%o Al Millar",1000,IF(I37="% Al Porciento",100,IF(I37="$ Prima",G37))) -> 1000 | S37: =IF(E37="Excluido",0,IF(D37="NO APLICA",0,1)) -> 1
A38: 904 | B38: 1 | C38: TERREMOTO EDIFICIO | D38: =$D$17 -> INCLUIDO | M38: =M31 -> 0.05 | P38: =IF(Q38=1,"SI","NO") -> NO | Q38: =IF(D38="INCLUIDO",IF(F39<>0,1,0),0) -> 0
A39: TEV | B39: 044 | C39: REMOCIÓN DE ESCOMBROS FENÓMENOS HIDROMETEOROLÓGICOS | D39: =$D$17 -> INCLUIDO | E39: Sublimite | F39: 0 | G39: ='COTIZACIÓN M.N.'!E62 -> 0.04 | H39: =(((IF(I39="$ Prima",G39,G39*F39/R39))*$U$9)/365)*$J$15 -> 0 | I39: %o Al Millar | J39: =H39*$U$7 -> 0 | K39: =(H39+J39)*$K$15 -> 0 | L39: =ROUND(H39+J39+K39,2) -> 0 | M39: =M38 -> 0.05 | N39: =H39*M39 -> 0 | O39: =N39 -> 0 | P39: =IF(Q39=1,"SI","NO") -> NO | Q39: =IF(D39="INCLUIDO",IF(F39<>0,1,0),0) -> 0 | R39: =IF(I39="%o Al Millar",1000,IF(I39="% Al Porciento",100,IF(I39="$ Prima",G39))) -> 1000 | S39: =IF(E39="Excluido",0,IF(D39="NO APLICA",0,1)) -> 1
C40: SUBTOTAL | D40: =D39 -> INCLUIDO | F40: =SUMIF(E18:E39,"Adicional",F18:F39) -> 20000000 | H40: =SUM(H18:H39) -> 0 | J40: =SUM(J18:J39) -> 0 | K40: =SUM(K18:K39) -> 0 | L40: =SUM(L18:L39) -> 0 | N40: =SUM(N18:N39) -> 0 | O40: =SUM(O18:O39) -> 0 | P40: =IF(Q40=1,"SI","NO") -> NO | Q40: =IF(D40="INCLUIDO",IF(H40<>0,1,0),0) -> 0
A41: 902 | B41: 2 | C41: INCENDIO CONTENIDOS | D41: =$D$17 -> INCLUIDO | F41: 0 | G41: ='COTIZACIÓN M.N.'!E33+'COTIZACIÓN M.N.'!E34+'COTIZACIÓN M.N.'!E35 -> 0.3078153 | M41: 0.25 | P41: =IF(Q41=1,"SI","NO") -> NO | Q41: =IF(D41="INCLUIDO",IF(F41<>0,1,0),0) -> 0 | T41: =G41 -> 0.3078153
...

Sheet Hoja Contable
S1: 3 | T1: =VLOOKUP(S1,S2:T5,2) -> TRIMESTRAL | U1: =IF(F13="NACIONAL",1,2) -> 2 | V1: =F13 -> DÓLARES
S2: 1 | T2: CONTADO | U2: 0 | V2: 0
S3: 2 | T3: SEMESTRAL | U3: 0.042 | V3: 0.014
S4: 3 | T4: TRIMESTRAL | U4: 0.064 | V4: 0.0211
A5: HOJA CONTABLE | S5: 4 | T5: MENSUAL | U5: 0.077 | V5: 0.0258
A7: RAMO COMERCIAL | C7: 20 - SME 1ER RIESGO - ESPARCIMIENTO | K7: =MID(C7,1,2)*1 -> 20 | L7: POLIZA A PRIMER RIESGO | S7: Recargo Forma de Pago: | U7: =VLOOKUP(S1,S2:V5,U1+2) -> 0.0211
A8: GIRO | C8: 0590-ESPECTÁCULOS PÚBLICOS, CINES, TEATROS, PARQUES DE DIVERSIÓN, CASINOS Y/O SIMILARES | F8: SUBGIRO | G8: 0590.05-Cines | L8: =Hoja3!A8
A9: ASEGURADO | C9: OPERADORA DE CINEMAS SA DE CV | J9: COD. ASEG. | K9: 0 | L9: TIPO DE MOVIMIENTO | N9: POLIZA NUEVA | S9: Factor Prorrata: | U9: =IF(H14="DIRECTA",1,J15/I15) -> 1
A10: DIRECCIÓN FISCAL | C10: JAVIER BARROS SIERRA 540 TORRE 1 PH1 COL SANTA FE ALVARO OBREGON CDMX CP 01210 | L10: TIPO DE PÓLIZA | N10: TODO RIESGO
A11: DIRECCIÓN DEL RIESGO | C11: =C10 -> JAVIER BARROS SIERRA 540 TORRE 1 PH1 COL SANTA FE ALVARO OBREGON CDMX CP 01210 | L11: ZONA TEV | M11: ='COTIZACIÓN M.N.'!G13 -> A | N11: ZONA F.H.M. | O11: ='COTIZACIÓN M.N.'!G17 -> A1PS
A12: VIG. INICIO | C12: 45107 | D12: T. DE RIESGO: | F12: ORDINARIO | G12: AGENTE | H12: MARSH | K12: 1 | L12: REM. ESC. | M12: ='COTIZACIÓN M.N.'!G15 -> 0.2 | N12: Indice Variable | O12: ='COTIZACIÓN M.N.'!G16 -> 0
A13: VIG. FINAL | C13: 45473 | D13: MONEDA | F13: DÓLARES | G13: R.F.C. | H13: OCI970818KX9 | J13: DÍAS DE VIGENCIA | N13: Coaseguro FHM | O13: =100%-'COTIZACIÓN M.N.'!G18 -> 1
A14: PÓLIZA | C14: POLIZA NUEVA | D14: F. PAGO | G14: CALCULO | H14: DIRECTA | K14: IVA | N14: Coaseguro TEV | O14: =100%-'COTIZACIÓN M.N.'!G14 -> 1
C15: 1 | I15: 365 | J15: =C13-C12 -> 366 | K15: 0.16
A16: COD. RAMO TECNICO | B16: SECCIÓN / COB. | C16: SECCIÓN / COBERTURA | D16: S/N | E16: Sublimite | F16: SUMA ASEGURADA | G16: CUOTAS | H16: PRIMA | I16: METODO DE CALCULO | J16: REC. PAGO FRACC. | K16: IVA | L16: PRIMA TOTAL | M16: COM. % | N16: COMISIÓN | O16: COMISIÓN TOTAL | P16: FILTRO
A17: 902 | B17: 001 | C17: INCENDIO EDIFICIO | D17: ='Ramo Comercial'!C121 -> INCLUIDO | F17: ='COTIZACIÓN M.N.'!D24 -> 155549.7 | G17: ='COTIZACIÓN M.N.'!E24+'COTIZACIÓN M.N.'!E25+'COTIZACIÓN M.N.'!E26 -> 0.3078153 | M17: 0.1201 | P17: =IF(Q17=1,"SI","NO") -> SI | Q17: =IF(D17="INCLUIDO",IF(F17<>0,1,0),0) -> 1 | T17: =G17 -> 0.3078153
A18: INCENDIO | B18: 001 | C18: COBERTURA BÁSICA | D18: =$D$17 -> INCLUIDO | E18: Sublimite | F18: =$F$17*S18 -> 155549.7 | G18: =V18 -> 0.24625224 | H18: =(((IF(I18="$ Prima",G18,G18*F18/R18))*$U$9)/365)*$J$15 -> 38.409406 | I18: %o Al Millar | J18: =H18*$U$7 -> 0.81043846 | K18: =(H18+J18)*$K$15 -> 6.2751751 | L18: =ROUND(H18+J18+K18,2) -> 45.5 | M18: =$M$17 -> 0.1201 | N18: =H18*M18 -> 4.6129696 | O18: =N18 -> 4.6129696 | P18: =IF(Q18=1,"SI","NO") -> SI | Q18: =IF(D18="INCLUIDO",IF(F18<>0,1,0),0) -> 1 | R18: =IF(I18="%o Al Millar",1000,IF(I18="% Al Porciento",100,IF(I18="$ Prima",G18))) -> 1000 | S18: =IF(E18="Excluido",0,IF(D18="NO APLICA",0,1)) -> 1 | T18: 0.8 | U18: =IF(E18="Excluido",0,T17*T18) -> 0.24625224 | V18: =IF(F17=0,0,(U23-U22-U20)+(T17-U23)) -> 0.24625224 | W18: ='UB (1)'!H18+'UB (2)'!H18+'UB (3)'!H18+#REF!+#REF!+#REF!+#REF!+#REF!+#REF!+#REF!+#REF!+#REF!+#REF!+#REF!+#REF!+#REF!+#REF!+#REF!+#REF!+#REF!+#REF!+#REF!+#REF!+#REF!+#REF!+#REF!+#REF!+#REF!+#REF!+#REF!+#REF!+#REF!+#REF!+#REF!+#REF!+#REF!+#REF!+#REF!+#REF!+#REF!+#REF!+#REF!+#REF!+#REF!+#REF!+#REF!+#REF!+#REF!+#REF!+#REF!+#REF!+#REF!+#REF!+#REF!+#REF!+#REF!+#REF!+#REF!+#REF!+#REF!+#REF!+#REF!+#REF!+#REF!+#REF!+#REF!+#REF!+#REF!+#REF!+#REF!+#REF!+#REF!+#REF!+#REF!+#REF!+#REF!+#REF!+#REF!+#REF!+#REF!+#REF!+#REF!+#REF!+#REF!+#REF!+#REF!+#REF!+#REF!+#REF!+#REF!+#REF!+#REF!+#REF!+#REF!+#REF!+#REF!+#REF!+#REF!+#REF!+#REF!+#REF!+#REF!+#REF!+#REF!+#REF!+#REF!+#REF!+#REF!+#REF!+#REF!+#REF!+#REF!+#REF!+#REF!+#REF!+#REF!+#REF!+#REF!+#REF!+#REF!+#REF!+#REF!+#REF!+#REF!+#REF!+#REF!+#REF!+#REF!+#REF!+#REF!+#REF!+#REF!+#REF!+#REF!+#REF!+#REF!+#REF!+#REF!+#REF!+#REF!+#REF!+#REF!+#REF!+#REF!+#REF!+#REF!+#REF!+#REF!+#REF!+#REF!+#REF!+#REF!+#REF!+#REF!+#REF!+#REF!+#REF!+#REF!+#REF!+#REF!+#REF!+#REF!+#REF!+#REF!+#REF!+#REF!+#REF!+#REF!+#REF!+#REF!+#REF!+#REF!+#REF!+#REF!+#REF!+#REF!+#REF!+#REF!+#REF!+#REF!+#REF!+#REF!+#REF!+#REF!+#REF!+#REF!+#REF!+#REF!+#REF!+#REF!+#REF!+#REF!+#REF!+#REF!+#REF!+#REF!+#REF!+#REF!+#REF!+#REF!+#REF!+#REF!+#REF!+#REF!+#REF!+#REF!+#REF!+#REF!+#REF!+#REF!+#REF!+#REF!+#REF!+#REF!+#REF!+#REF!+#REF!+#REF!+#REF!+#REF!+#REF!+#REF!+#REF!+#REF!+#REF!+#REF!+#REF!+#REF!+#REF!+#REF!+#REF!+#REF!+#REF!+#REF!+#REF!+#REF!+#REF!+#REF!+#REF!+#REF!+#REF!+#REF!+#REF!+#REF!+#REF!+#REF!+#REF!+#REF!+#REF!+#REF!+#REF!+#REF!+#REF!+#REF!+#REF!+#REF!+#REF!+#REF!+#REF!+#REF!+#REF!+#REF!+#REF!+#REF!+#REF!+#REF!+#REF!+#REF!+#REF!+#REF!+#REF!+#REF!+#REF!+#REF!+#REF!+#REF!+#REF!+#REF!+#REF!+#REF!+#REF!+#REF!+#REF!+#REF!+#REF!+#REF!+#REF!+#REF!+#REF!+#REF!+#REF!+#REF!+#REF!+#REF!+#REF!+#REF!+#REF!+#REF!+#REF!+#REF!+#REF!+#REF!+#REF!+#REF!+#REF!+#REF!+#REF!+#REF!+#REF!+#REF!+#REF!+#REF!+#REF!+#REF!+#REF!+#REF!+#REF!+#REF!+#REF!+#REF!+#REF!+#REF!+#REF!+#REF!+#REF!+#REF!+#REF!+#REF!+#REF!+#REF!+#REF!+#REF!+#REF!+#REF!+#REF!+#REF!+#REF!+#REF!+#REF!+#REF!+#REF!+#REF!+#REF!+#REF!+#REF!+#REF!+#REF!+#REF!+#REF!+#REF!+#REF!+#REF!+#REF!+#REF!+#REF!+#REF!+#REF!+#REF!+#REF!+#REF!+#REF!+#REF!+#REF!+#REF! -> #REF!
A19: INCENDIO | C19: =$O$12 -> 0 | D19: =$D$17 -> INCLUIDO | E19: Adicional | F19: =(F18*$O$12)*S19 -> 0 | G19: =G18*0.35 -> 0.086188284 | H19: =(IF(I19="$ Prima",G19,G19*F19/R19))*$U$9 -> 0 | I19: %o Al Millar | J19: =H19*$U$7 -> 0 | K19: =(H19+J19)*$K$15 -> 0 | L19: =ROUND(H19+J19+K19,2) -> 0 | M19: =$M$17 -> 0.1201 | N19: =H19*M19 -> 0 | O19: =N19 -> 0 | P19: =IF(Q19=1,"SI","NO") -> NO | Q19: =IF(D19="INCLUIDO",IF(F19<>0,1,0),0) -> 0 | R19: =IF(I19="%o Al Millar",1000,IF(I19="% Al Porciento",100,IF(I19="$ Prima",G19))) -> 1000 | S19: =IF(E19="Excluido",0,IF(D19="NO APLICA",0,1)) -> 1
A20: INCENDIO | B20: 002 | C20: EXTENSIÓN DE CUBIERTA (SIN HURACÁN Y GRANIZO) | D20: =$D$17 -> INCLUIDO | E20: Sublimite | F20: =$F$17*S20 -> 155549.7 | G20: =V20 -> 0.03078153 | H20: =(((IF(I20="$ Prima",G20,G20*F20/R20))*$U$9)/365)*$J$15 -> 4.8011757 | I20: %o Al Millar | J20: =H20*$U$7 -> 0.10130481 | K20: =(H20+J20)*$K$15 -> 0.78439689 | L20: =ROUND(H20+J20+K20,2) -> 5.69 | M20: =$M$17 -> 0.1201 | N20: =H20*M20 -> 0.5766212 | O20: =N20 -> 0.5766212 | P20: =IF(Q20=1,"SI","NO") -> SI | Q20: =IF(D20="INCLUIDO",IF(F20<>0,1,0),0) -> 1 | R20: =IF(I20="%o Al Millar",1000,IF(I20="% Al Porciento",100,IF(I20="$ Prima",G20))) -> 1000 | S20: =IF(E20="Excluido",0,IF(D20="NO APLICA",0,1)) -> 1 | T20: 0.1 | U20: =IF(E20="Excluido",0,T17*T20) -> 0.03078153 | V20: =IF(F$17=0,0,U20) -> 0.03078153 | W20: ='UB (1)'!H20+'UB (2)'!H20+'UB (3)'!H20+#REF!+#REF!+#REF!+#REF!+#REF!+#REF!+#REF!+#REF!+#REF!+#REF!+#REF!+#REF!+#REF!+#REF!+#REF!+#REF!+#REF!+#REF!+#REF!+#REF!+#REF!+#REF!+#REF!+#REF!+#REF!+#REF!+#REF!+#REF!+#REF!+#REF!+#REF!+#REF!+#REF!+#REF!+#REF!+#REF!+#REF!+#REF!+#REF!+#REF!+#REF!+#REF!+#REF!+#REF!+#REF!+#REF!+#REF!+#REF!+#REF!+#REF!+#REF!+#REF!+#REF!+#REF!+#REF!+#REF!+#REF!+#REF!+#REF!+#REF!+#REF!+#REF!+#REF!+#REF!+#REF!+#REF!+#REF!+#REF!+#REF!+#REF!+#REF!+#REF!+#REF!+#REF!+#REF!+#REF!+#REF!+#REF!+#REF!+#REF!+#REF!+#REF!+#REF!+#REF!+#REF!+#REF!+#REF!+#REF!+#REF!+#REF!+#REF!+#REF!+#REF!+#REF!+#REF!+#REF!+#REF!+#REF!+#REF!+#REF!+#REF!+#REF!+#REF!+#REF!+#REF!+#REF!+#REF!+#REF!+#REF!+#REF!+#REF!+#REF!+#REF!+#REF!+#REF!+#REF!+#REF!+#REF!+#REF!+#REF!+#REF!+#REF!+#REF!+#REF!+#REF!+#REF!+#REF!+#REF!+#REF!+#REF!+#REF!+#REF!+#REF!+#REF!+#REF!+#REF!+#REF!+#REF!+#REF!+#REF!+#REF!+#REF!+#REF!+#REF!+#REF!+#REF!+#REF!+#REF!+#REF!+#REF!+#REF!+#REF!+#REF!+#REF!+#REF!+#REF!+#REF!+#REF!+#REF!+#REF!+#REF!+#REF!+#REF!+#REF!+#REF!+#REF!+#REF!+#REF!+#REF!+#REF!+#REF!+#REF!+#REF!+#REF!+#REF!+#REF!+#REF!+#REF!+#REF!+#REF!+#REF!+#REF!+#REF!+#REF!+#REF!+#REF!+#REF!+#REF!+#REF!+#REF!+#REF!+#REF!+#REF!+#REF!+#REF!+#REF!+#REF!+#REF!+#REF!+#REF!+#REF!+#REF!+#REF!+#REF!+#REF!+#REF!+#REF!+#REF!+#REF!+#REF!+#REF!+#REF!+#REF!+#REF!+#REF!+#REF!+#REF!+#REF!+#REF!+#REF!+#REF!+#REF!+#REF!+#REF!+#REF!+#REF!+#REF!+#REF!+#REF!+#REF!+#REF!+#REF!+#REF!+#REF!+#REF!+#REF!+#REF!+#REF!+#REF!+#REF!+#REF!+#REF!+#REF!+#REF!+#REF!+#REF!+#REF!+#REF!+#REF!+#REF!+#REF!+#REF!+#REF!+#REF!+#REF!+#REF!+#REF!+#REF!+#REF!+#REF!+#REF!+#REF!+#REF!+#REF!+#REF!+#REF!+#REF!+#REF!+#REF!+#REF!+#REF!+#REF!+#REF!+#REF!+#REF!+#REF!+#REF!+#REF!+#REF!+#REF!+#REF!+#REF!+#REF!+#REF!+#REF!+#REF!+#REF!+#REF!+#REF!+#REF!+#REF!+#REF!+#REF!+#REF!+#REF!+#REF!+#REF!+#REF!+#REF!+#REF!+#REF!+#REF!+#REF!+#REF!+#REF!+#REF!+#REF!+#REF!+#REF!+#REF!+#REF!+#REF!+#REF!+#REF!+#REF!+#REF!+#REF!+#REF!+#REF!+#REF!+#REF!+#REF!+#REF!+#REF!+#REF!+#REF!+#REF!+#REF!+#REF!+#REF!+#REF!+#REF!+#REF!+#REF!+#REF!+#REF!+#REF!+#REF!+#REF!+#REF!+#REF!+#REF!+#REF!+#REF!+#REF!+#REF!+#REF!+#REF!+#REF!+#REF!+#REF!+#REF!+#REF!+#REF!+#REF!+#REF!+#REF!+#REF!+#REF!+#REF!+#REF! -> #REF!
A21: INCENDIO | C21: =$O$12 -> 0 | D21: =$D$17 -> INCLUIDO | E21: =E20 -> Sublimite | F21: =(F20*$O$12)*S21 -> 0 | G21: =G20*0.35 -> 0.010773536 | H21: =(IF(I21="$ Prima",G21,G21*F21/R21))*$U$9 -> 0 | I21: %o Al Millar | J21: =H21*$U$7 -> 0 | K21: =(H21+J21)*$K$15 -> 0 | L21: =ROUND(H21+J21+K21,2) -> 0 | M21: =$M$17 -> 0.1201 | N21: =H21*M21 -> 0 | O21: =N21 -> 0 | P21: =IF(Q21=1,"SI","NO") -> NO | Q21: =IF(D21="INCLUIDO",IF(F21<>0,1,0),0) -> 0 | R21: =IF(I21="%o Al Millar",1000,IF(I21="% Al Porciento",100,IF(I21="$ Prima",G21))) -> 1000 | S21: =IF(E21="Excluido",0,IF(D21="NO APLICA",0,1)) -> 1
A22: INCENDIO | B22: 012 | C22: TODO RIESGO | D22: =$D$17 -> INCLUIDO | E22: Sublimite | F22: ='COTIZACIÓN M.N.'!D26 -> 155549.7 | G22: =V22 -> 0.03078153 | H22: =(((IF(I22="$ Prima",G22,G22*F22/R22))*$U$9)/365)*$J$15 -> 4.8011757 | I22: %o Al Millar | J22: =H22*$U$7 -> 0.10130481 | K22: =(H22+J22)*$K$15 -> 0.78439689 | L22: =ROUND(H22+J22+K22,2) -> 5.69 | M22: =$M$17 -> 0.1201 | N22: =H22*M22 -> 0.5766212 | O22: =N22 -> 0.5766212 | P22: =IF(Q22=1,"SI","NO") -> SI | Q22: =IF(D22="INCLUIDO",IF(F22<>0,1,0),0) -> 1 | R22: =IF(I22="%o Al Millar",1000,IF(I22="% Al Porciento",100,IF(I22="$ Prima",G22))) -> 1000 | S22: =IF(E22="Excluido",0,IF(D22="NO APLICA",0,1)) -> 1 | T22: 0.1 | U22: =IF(E22="Excluido",0,T17*T22) -> 0.03078153 | V22: =IF(F$17=0,0,U22) -> 0.03078153 | W22: ='UB (1)'!H22+'UB (2)'!H22+'UB (3)'!H22+#REF!+#REF!+#REF!+#REF!+#REF!+#REF!+#REF!+#REF!+#REF!+#REF!+#REF!+#REF!+#REF!+#REF!+#REF!+#REF!+#REF!+#REF!+#REF!+#REF!+#REF!+#REF!+#REF!+#REF!+#REF!+#REF!+#REF!+#REF!+#REF!+#REF!+#REF!+#REF!+#REF!+#REF!+#REF!+#REF!+#REF!+#REF!+#REF!+#REF!+#REF!+#REF!+#REF!+#REF!+#REF!+#REF!+#REF!+#REF!+#REF!+#REF!+#REF!+#REF!+#REF!+#REF!+#REF!+#REF!+#REF!+#REF!+#REF!+#REF!+#REF!+#REF!+#REF!+#REF!+#REF!+#REF!+#REF!+#REF!+#REF!+#REF!+#REF!+#REF!+#REF!+#REF!+#REF!+#REF!+#REF!+#REF!+#REF!+#REF!+#REF!+#REF!+#REF!+#REF!+#REF!+#REF!+#REF!+#REF!+#REF!+#REF!+#REF!+#REF!+#REF!+#REF!+#REF!+#REF!+#REF!+#REF!+#REF!+#REF!+#REF!+#REF!+#REF!+#REF!+#REF!+#REF!+#REF!+#REF!+#REF!+#REF!+#REF!+#REF!+#REF!+#REF!+#REF!+#REF!+#REF!+#REF!+#REF!+#REF!+#REF!+#REF!+#REF!+#REF!+#REF!+#REF!+#REF!+#REF!+#REF!+#REF!+#REF!+#REF!+#REF!+#REF!+#REF!+#REF!+#REF!+#REF!+#REF!+#REF!+#REF!+#REF!+#REF!+#REF!+#REF!+#REF!+#REF!+#REF!+#REF!+#REF!+#REF!+#REF!+#REF!+#REF!+#REF!+#REF!+#REF!+#REF!+#REF!+#REF!+#REF!+#REF!+#REF!+#REF!+#REF!+#REF!+#REF!+#REF!+#REF!+#REF!+#REF!+#REF!+#REF!+#REF!+#REF!+#REF!+#REF!+#REF!+#REF!+#REF!+#REF!+#REF!+#REF!+#REF!+#REF!+#REF!+#REF!+#REF!+#REF!+#REF!+#REF!+#REF!+#REF!+#REF!+#REF!+#REF!+#REF!+#REF!+#REF!+#REF!+#REF!+#REF!+#REF!+#REF!+#REF!+#REF!+#REF!+#REF!+#REF!+#REF!+#REF!+#REF!+#REF!+#REF!+#REF!+#REF!+#REF!+#REF!+#REF!+#REF!+#REF!+#REF!+#REF!+#REF!+#REF!+#REF!+#REF!+#REF!+#REF!+#REF!+#REF!+#REF!+#REF!+#REF!+#REF!+#REF!+#REF!+#REF!+#REF!+#REF!+#REF!+#REF!+#REF!+#REF!+#REF!+#REF!+#REF!+#REF!+#REF!+#REF!+#REF!+#REF!+#REF!+#REF!+#REF!+#REF!+#REF!+#REF!+#REF!+#REF!+#REF!+#REF!+#REF!+#REF!+#REF!+#REF!+#REF!+#REF!+#REF!+#REF!+#REF!+#REF!+#REF!+#REF!+#REF!+#REF!+#REF!+#REF!+#REF!+#REF!+#REF!+#REF!+#REF!+#REF!+#REF!+#REF!+#REF!+#REF!+#REF!+#REF!+#REF!+#REF!+#REF!+#REF!+#REF!+#REF!+#REF!+#REF!+#REF!+#REF!+#REF!+#REF!+#REF!+#REF!+#REF!+#REF!+#REF!+#REF!+#REF!+#REF!+#REF!+#REF!+#REF!+#REF!+#REF!+#REF!+#REF!+#REF!+#REF!+#REF!+#REF!+#REF!+#REF!+#REF!+#REF!+#REF!+#REF!+#REF!+#REF!+#REF!+#REF!+#REF!+#REF!+#REF!+#REF!+#REF!+#REF!+#REF!+#REF!+#REF!+#REF!+#REF!+#REF!+#REF!+#REF!+#REF!+#REF!+#REF!+#REF!+#REF!+#REF!+#REF!+#REF!+#REF!+#REF!+#REF!+#REF!+#REF!+#REF!+#REF!+#REF! -> #REF!
A23: INCENDIO | C23: =$O$12 -> 0 | D23: =$D$17 -> INCLUIDO | E23: =E22 -> Sublimite | F23: =(F22*$O$12)*S23 -> 0 | G23: =G22*0.35 -> 0.010773536 | H23: =(IF(I23="$ Prima",G23,G23*F23/R23))*$U$9 -> 0 | I23: %o Al Millar | J23: =H23*$U$7 -> 0 | K23: =(H23+J23)*$K$15 -> 0 | L23: =ROUND(H23+J23+K23,2) -> 0 | M23: =$M$17 -> 0.1201 | N23: =H23*M23 -> 0 | O23: =N23 -> 0 | P23: =IF(Q23=1,"SI","NO") -> NO | Q23: =IF(D23="INCLUIDO",IF(F23<>0,1,0),0) -> 0 | R23: =IF(I23="%o Al Millar",1000,IF(I23="% Al Porciento",100,IF(I23="$ Prima",G23))) -> 1000 | S23: =IF(E23="Excluido",0,IF(D23="NO APLICA",0,1)) -> 1 | T23: =SUM(T18:T22) -> 1 | U23: =SUM(U18:U22) -> 0.3078153 | V23: =SUM(V18:V22) -> 0.3078153
A24: INCENDIO | B24: 280 | C24: MEJORAS Y ADAPTACIONES | D24: =$D$17 -> INCLUIDO | E24: Sublimite | F24: 0 | G24: 0 | H24: =(IF(I24="$ Prima",G24,G24*F24/R24))*$U$9 -> 0 | I24: %o Al Millar | J24: =H24*$U$7 -> 0 | K24: =(H24+J24)*$K$15 -> 0 | L24: =ROUND(H24+J24+K24,2) -> 0 | M24: =$M$17 -> 0.1201 | N24: =H24*M24 -> 0 | O24: =N24 -> 0 | P24: =IF(Q24=1,"SI","NO") -> NO | Q24: =IF(D24="INCLUIDO",IF(F24<>0,1,0),0) -> 0 | R24: =IF(I24="%o Al Millar",1000,IF(I24="% Al Porciento",100,IF(I24="$ Prima",G24))) -> 1000 | S24: =IF(E24="Excluido",0,IF(D24="NO APLICA",0,1)) -> 1
A25: INCENDIO | C25: =$O$12 -> 0 | D25: =$D$17 -> INCLUIDO | E25: =E24 -> Sublimite | F25: =(F24*$O$12)*S25 -> 0 | G25: =G24*0.35 -> 0 | H25: =(IF(I25="$ Prima",G25,G25*F25/R25))*$U$9 -> 0 | I25: %o Al Millar | J25: =H25*$U$7 -> 0 | K25: =(H25+J25)*$K$15 -> 0 | L25: =ROUND(H25+J25+K25,2) -> 0 | M25: =$M$17 -> 0.1201 | N25: =H25*M25 -> 0 | O25: =N25 -> 0 | P25: =IF(Q25=1,"SI","NO") -> NO | Q25: =IF(D25="INCLUIDO",IF(F25<>0,1,0),0) -> 0 | R25: =IF(I25="%o Al Millar",1000,IF(I25="% Al Porciento",100,IF(I25="$ Prima",G25))) -> 1000 | S25: =IF(E25="Excluido",0,IF(D25="NO APLICA",0,1)) -> 1
